<robot name = "robot">
    <material name="blue">
        <color rgba="0 0.5 1.0 1.0"/>
    </material>
    <material name="green">
        <color rgba="0 1.0 0 1.0"/>
    </material>
    <link name="Limb0">
        <inertial>
            <origin xyz="0 0 1.0" rpy="0 0 0"/>
            <mass value="1" />
            <inertia ixx="100" ixy="0" ixz="0" iyy="100" iyz="0" izz="100" />
        </inertial>
        <visual>
            <origin xyz="0 0 1.0" rpy="0 0 0"/>
            <geometry>
                <box size="1.6 2.4 2.0" />
            </geometry>
    <material name="blue"/>
        </visual>
        <collision>
            <origin xyz="0 0 1.0" rpy="0 0 0"/>
            <geometry>
                <box size="1.6 2.4 2.0" />
            </geometry>
        </collision>
    </link>
    <joint name="Limb0_Limb1" type="revolute">
       <parent link="Limb0"/>
       <child  link="Limb1"/>
       <origin rpy="0 0 0" xyz="0 1.2 0" />
     <axis xyz="1 0 0"/>
       <limit effort="0.0" lower="-3.14159" upper="3.14159" velocity="0.0"/>
    </joint>
    <link name="Limb1">
        <inertial>
            <origin xyz="0 0.9 1.0" rpy="0 0 0"/>
            <mass value="1" />
            <inertia ixx="100" ixy="0" ixz="0" iyy="100" iyz="0" izz="100" />
        </inertial>
        <visual>
            <origin xyz="0 0.9 1.0" rpy="0 0 0"/>
            <geometry>
                <box size="2.7 1.8 2.0" />
            </geometry>
    <material name="green"/>
        </visual>
        <collision>
            <origin xyz="0 0.9 1.0" rpy="0 0 0"/>
            <geometry>
                <box size="2.7 1.8 2.0" />
            </geometry>
        </collision>
    </link>
    <joint name="Limb1_Limb2" type="revolute">
       <parent link="Limb1"/>
       <child  link="Limb2"/>
       <origin rpy="0 0 0" xyz="0 1.8 0" />
     <axis xyz="1 0 0"/>
       <limit effort="0.0" lower="-3.14159" upper="3.14159" velocity="0.0"/>
    </joint>
    <link name="Limb2">
        <inertial>
            <origin xyz="0 1.0 1.0" rpy="0 0 0"/>
            <mass value="1" />
            <inertia ixx="100" ixy="0" ixz="0" iyy="100" iyz="0" izz="100" />
        </inertial>
        <visual>
            <origin xyz="0 1.0 1.0" rpy="0 0 0"/>
            <geometry>
                <box size="2.3 2.0 2.0" />
            </geometry>
    <material name="green"/>
        </visual>
        <collision>
            <origin xyz="0 1.0 1.0" rpy="0 0 0"/>
            <geometry>
                <box size="2.3 2.0 2.0" />
            </geometry>
        </collision>
    </link>
    <joint name="Limb2_Limb3" type="revolute">
       <parent link="Limb2"/>
       <child  link="Limb3"/>
       <origin rpy="0 0 0" xyz="0 2.0 0" />
     <axis xyz="1 0 0"/>
       <limit effort="0.0" lower="-3.14159" upper="3.14159" velocity="0.0"/>
    </joint>
    <link name="Limb3">
        <inertial>
            <origin xyz="0 1.0 1.0" rpy="0 0 0"/>
            <mass value="1" />
            <inertia ixx="100" ixy="0" ixz="0" iyy="100" iyz="0" izz="100" />
        </inertial>
        <visual>
            <origin xyz="0 1.0 1.0" rpy="0 0 0"/>
            <geometry>
                <box size="2.3 2.0 2.0" />
            </geometry>
    <material name="green"/>
        </visual>
        <collision>
            <origin xyz="0 1.0 1.0" rpy="0 0 0"/>
            <geometry>
                <box size="2.3 2.0 2.0" />
            </geometry>
        </collision>
    </link>
    <joint name="Limb3_Limb4" type="revolute">
       <parent link="Limb3"/>
       <child  link="Limb4"/>
       <origin rpy="0 0 0" xyz="0 2.0 0" />
     <axis xyz="1 0 0"/>
       <limit effort="0.0" lower="-3.14159" upper="3.14159" velocity="0.0"/>
    </joint>
    <link name="Limb4">
        <inertial>
            <origin xyz="0 0.65 1.0" rpy="0 0 0"/>
            <mass value="1" />
            <inertia ixx="100" ixy="0" ixz="0" iyy="100" iyz="0" izz="100" />
        </inertial>
        <visual>
            <origin xyz="0 0.65 1.0" rpy="0 0 0"/>
            <geometry>
                <box size="2.5 1.3 2.0" />
            </geometry>
    <material name="green"/>
        </visual>
        <collision>
            <origin xyz="0 0.65 1.0" rpy="0 0 0"/>
            <geometry>
                <box size="2.5 1.3 2.0" />
            </geometry>
        </collision>
    </link>
    <joint name="Limb4_Limb5" type="revolute">
       <parent link="Limb4"/>
       <child  link="Limb5"/>
       <origin rpy="0 0 0" xyz="0 1.3 0" />
     <axis xyz="1 0 0"/>
       <limit effort="0.0" lower="-3.14159" upper="3.14159" velocity="0.0"/>
    </joint>
    <link name="Limb5">
        <inertial>
            <origin xyz="0 1.2 1.0" rpy="0 0 0"/>
            <mass value="1" />
            <inertia ixx="100" ixy="0" ixz="0" iyy="100" iyz="0" izz="100" />
        </inertial>
        <visual>
            <origin xyz="0 1.2 1.0" rpy="0 0 0"/>
            <geometry>
                <box size="2.0 2.4 2.0" />
            </geometry>
    <material name="blue"/>
        </visual>
        <collision>
            <origin xyz="0 1.2 1.0" rpy="0 0 0"/>
            <geometry>
                <box size="2.0 2.4 2.0" />
            </geometry>
        </collision>
    </link>
    <joint name="Limb5_Limb6" type="revolute">
       <parent link="Limb5"/>
       <child  link="Limb6"/>
       <origin rpy="0 0 0" xyz="0 2.4 0" />
     <axis xyz="1 0 0"/>
       <limit effort="0.0" lower="-3.14159" upper="3.14159" velocity="0.0"/>
    </joint>
    <link name="Limb6">
        <inertial>
            <origin xyz="0 0.65 1.0" rpy="0 0 0"/>
            <mass value="1" />
            <inertia ixx="100" ixy="0" ixz="0" iyy="100" iyz="0" izz="100" />
        </inertial>
        <visual>
            <origin xyz="0 0.65 1.0" rpy="0 0 0"/>
            <geometry>
                <box size="1.8 1.3 2.0" />
            </geometry>
    <material name="blue"/>
        </visual>
        <collision>
            <origin xyz="0 0.65 1.0" rpy="0 0 0"/>
            <geometry>
                <box size="1.8 1.3 2.0" />
            </geometry>
        </collision>
    </link>
    <joint name="Limb6_Limb7" type="revolute">
       <parent link="Limb6"/>
       <child  link="Limb7"/>
       <origin rpy="0 0 0" xyz="0 1.3 0" />
     <axis xyz="1 0 0"/>
       <limit effort="0.0" lower="-3.14159" upper="3.14159" velocity="0.0"/>
    </joint>
    <link name="Limb7">
        <inertial>
            <origin xyz="0 1.3 1.0" rpy="0 0 0"/>
            <mass value="1" />
            <inertia ixx="100" ixy="0" ixz="0" iyy="100" iyz="0" izz="100" />
        </inertial>
        <visual>
            <origin xyz="0 1.3 1.0" rpy="0 0 0"/>
            <geometry>
                <box size="2.1 2.6 2.4" />
            </geometry>
    <material name="blue"/>
        </visual>
        <collision>
            <origin xyz="0 1.3 1.0" rpy="0 0 0"/>
            <geometry>
                <box size="2.1 2.6 2.4" />
            </geometry>
        </collision>
    </link>
    <joint name="Limb3_Limb10" type="revolute">
       <parent link="Limb3"/>
       <child  link="Limb10"/>
       <origin rpy="0 0 0" xyz="1.15 0 0" />
     <axis xyz="0 1 0"/>
       <limit effort="0.0" lower="-3.14159" upper="3.14159" velocity="0.0"/>
    </joint>
    <link name="Limb10">
        <inertial>
            <origin xyz="1.15 0 1.0" rpy="0 0 0"/>
            <mass value="1" />
            <inertia ixx="100" ixy="0" ixz="0" iyy="100" iyz="0" izz="100" />
        </inertial>
        <visual>
            <origin xyz="1.15 0 1.0" rpy="0 0 0"/>
            <geometry>
                <box size="2.3 2.6 2.4" />
            </geometry>
    <material name="blue"/>
        </visual>
        <collision>
            <origin xyz="1.15 0 1.0" rpy="0 0 0"/>
            <geometry>
                <box size="2.3 2.6 2.4" />
            </geometry>
        </collision>
    </link>
    <joint name="Limb10_Limb11" type="revolute">
       <parent link="Limb10"/>
       <child  link="Limb11"/>
       <origin rpy="0 0 0" xyz="2.3 0 0" />
     <axis xyz="0 1 0"/>
       <limit effort="0.0" lower="-3.14159" upper="3.14159" velocity="0.0"/>
    </joint>
    <link name="Limb11">
        <inertial>
            <origin xyz="0.6 0 1.0" rpy="0 0 0"/>
            <mass value="1" />
            <inertia ixx="100" ixy="0" ixz="0" iyy="100" iyz="0" izz="100" />
        </inertial>
        <visual>
            <origin xyz="0.6 0 1.0" rpy="0 0 0"/>
            <geometry>
                <box size="1.2 2.6 2.4" />
            </geometry>
    <material name="blue"/>
        </visual>
        <collision>
            <origin xyz="0.6 0 1.0" rpy="0 0 0"/>
            <geometry>
                <box size="1.2 2.6 2.4" />
            </geometry>
        </collision>
    </link>
    <joint name="Limb11_Limb12" type="revolute">
       <parent link="Limb11"/>
       <child  link="Limb12"/>
       <origin rpy="0 0 0" xyz="1.2 0 0" />
     <axis xyz="0 1 0"/>
       <limit effort="0.0" lower="-3.14159" upper="3.14159" velocity="0.0"/>
    </joint>
    <link name="Limb12">
        <inertial>
            <origin xyz="1.45 0 1.0" rpy="0 0 0"/>
            <mass value="1" />
            <inertia ixx="100" ixy="0" ixz="0" iyy="100" iyz="0" izz="100" />
        </inertial>
        <visual>
            <origin xyz="1.45 0 1.0" rpy="0 0 0"/>
            <geometry>
                <box size="2.9 2.6 2.4" />
            </geometry>
    <material name="blue"/>
        </visual>
        <collision>
            <origin xyz="1.45 0 1.0" rpy="0 0 0"/>
            <geometry>
                <box size="2.9 2.6 2.4" />
            </geometry>
        </collision>
    </link>
    <joint name="Limb12_Limb13" type="revolute">
       <parent link="Limb12"/>
       <child  link="Limb13"/>
       <origin rpy="0 0 0" xyz="2.9 0 0" />
     <axis xyz="0 1 0"/>
       <limit effort="0.0" lower="-3.14159" upper="3.14159" velocity="0.0"/>
    </joint>
    <link name="Limb13">
        <inertial>
            <origin xyz="1.0 0 1.0" rpy="0 0 0"/>
            <mass value="1" />
            <inertia ixx="100" ixy="0" ixz="0" iyy="100" iyz="0" izz="100" />
        </inertial>
        <visual>
            <origin xyz="1.0 0 1.0" rpy="0 0 0"/>
            <geometry>
                <box size="2.0 2.6 2.4" />
            </geometry>
    <material name="blue"/>
        </visual>
        <collision>
            <origin xyz="1.0 0 1.0" rpy="0 0 0"/>
            <geometry>
                <box size="2.0 2.6 2.4" />
            </geometry>
        </collision>
    </link>
    <joint name="Limb13_Limb14" type="revolute">
       <parent link="Limb13"/>
       <child  link="Limb14"/>
       <origin rpy="0 0 0" xyz="2.0 0 0" />
     <axis xyz="0 1 0"/>
       <limit effort="0.0" lower="-3.14159" upper="3.14159" velocity="0.0"/>
    </joint>
    <link name="Limb14">
        <inertial>
            <origin xyz="0.5 0 1.0" rpy="0 0 0"/>
            <mass value="1" />
            <inertia ixx="100" ixy="0" ixz="0" iyy="100" iyz="0" izz="100" />
        </inertial>
        <visual>
            <origin xyz="0.5 0 1.0" rpy="0 0 0"/>
            <geometry>
                <box size="1.0 2.6 2.4" />
            </geometry>
    <material name="blue"/>
        </visual>
        <collision>
            <origin xyz="0.5 0 1.0" rpy="0 0 0"/>
            <geometry>
                <box size="1.0 2.6 2.4" />
            </geometry>
        </collision>
    </link>
    <joint name="Limb14_Limb15" type="revolute">
       <parent link="Limb14"/>
       <child  link="Limb15"/>
       <origin rpy="0 0 0" xyz="1.0 0 0" />
     <axis xyz="0 1 0"/>
       <limit effort="0.0" lower="-3.14159" upper="3.14159" velocity="0.0"/>
    </joint>
    <link name="Limb15">
        <inertial>
            <origin xyz="0.75 0 1.0" rpy="0 0 0"/>
            <mass value="1" />
            <inertia ixx="100" ixy="0" ixz="0" iyy="100" iyz="0" izz="100" />
        </inertial>
        <visual>
            <origin xyz="0.75 0 1.0" rpy="0 0 0"/>
            <geometry>
                <box size="1.5 2.6 2.4" />
            </geometry>
    <material name="blue"/>
        </visual>
        <collision>
            <origin xyz="0.75 0 1.0" rpy="0 0 0"/>
            <geometry>
                <box size="1.5 2.6 2.4" />
            </geometry>
        </collision>
    </link>
    <joint name="Limb5_Limb16" type="revolute">
       <parent link="Limb5"/>
       <child  link="Limb16"/>
       <origin rpy="0 0 0" xyz="-1.0 0 0" />
     <axis xyz="0 1 0"/>
       <limit effort="0.0" lower="-3.14159" upper="3.14159" velocity="0.0"/>
    </joint>
    <link name="Limb16">
        <inertial>
            <origin xyz="-0.6 0 1.0" rpy="0 0 0"/>
            <mass value="1" />
            <inertia ixx="100" ixy="0" ixz="0" iyy="100" iyz="0" izz="100" />
        </inertial>
        <visual>
            <origin xyz="-0.6 0 1.0" rpy="0 0 0"/>
            <geometry>
                <box size="1.2 2.6 2.4" />
            </geometry>
    <material name="blue"/>
        </visual>
        <collision>
            <origin xyz="-0.6 0 1.0" rpy="0 0 0"/>
            <geometry>
                <box size="1.2 2.6 2.4" />
            </geometry>
        </collision>
    </link>
</robot>