<robot name = "robot">
    <material name="blue">
        <color rgba="0 0.5 1.0 1.0"/>
    </material>
    <material name="green">
        <color rgba="0 1.0 0 1.0"/>
    </material>
    <link name="Limb0">
        <inertial>
            <origin xyz="0 0 1.0" rpy="0 0 0"/>
            <mass value="1" />
            <inertia ixx="100" ixy="0" ixz="0" iyy="100" iyz="0" izz="100" />
        </inertial>
        <visual>
            <origin xyz="0 0 1.0" rpy="0 0 0"/>
            <geometry>
                <box size="2.1 1.5 2.8" />
            </geometry>
    <material name="blue"/>
        </visual>
        <collision>
            <origin xyz="0 0 1.0" rpy="0 0 0"/>
            <geometry>
                <box size="2.1 1.5 2.8" />
            </geometry>
        </collision>
    </link>
    <joint name="Limb0_Limb1" type="revolute">
       <parent link="Limb0"/>
       <child  link="Limb1"/>
       <origin rpy="0 0 0" xyz="0 0.75 0" />
     <axis xyz="1 0 0"/>
       <limit effort="0.0" lower="-3.14159" upper="3.14159" velocity="0.0"/>
    </joint>
    <link name="Limb1">
        <inertial>
            <origin xyz="0 0.9 1.0" rpy="0 0 0"/>
            <mass value="1" />
            <inertia ixx="100" ixy="0" ixz="0" iyy="100" iyz="0" izz="100" />
        </inertial>
        <visual>
            <origin xyz="0 0.9 1.0" rpy="0 0 0"/>
            <geometry>
                <box size="2.4 1.8 2.8" />
            </geometry>
    <material name="blue"/>
        </visual>
        <collision>
            <origin xyz="0 0.9 1.0" rpy="0 0 0"/>
            <geometry>
                <box size="2.4 1.8 2.8" />
            </geometry>
        </collision>
    </link>
    <joint name="Limb1_Limb2" type="revolute">
       <parent link="Limb1"/>
       <child  link="Limb2"/>
       <origin rpy="0 0 0" xyz="0 1.8 0" />
     <axis xyz="1 0 0"/>
       <limit effort="0.0" lower="-3.14159" upper="3.14159" velocity="0.0"/>
    </joint>
    <link name="Limb2">
        <inertial>
            <origin xyz="0 1.35 1.0" rpy="0 0 0"/>
            <mass value="1" />
            <inertia ixx="100" ixy="0" ixz="0" iyy="100" iyz="0" izz="100" />
        </inertial>
        <visual>
            <origin xyz="0 1.35 1.0" rpy="0 0 0"/>
            <geometry>
                <box size="2.6 2.7 2.8" />
            </geometry>
    <material name="blue"/>
        </visual>
        <collision>
            <origin xyz="0 1.35 1.0" rpy="0 0 0"/>
            <geometry>
                <box size="2.6 2.7 2.8" />
            </geometry>
        </collision>
    </link>
    <joint name="Limb2_Limb3" type="revolute">
       <parent link="Limb2"/>
       <child  link="Limb3"/>
       <origin rpy="0 0 0" xyz="0 2.7 0" />
     <axis xyz="1 0 0"/>
       <limit effort="0.0" lower="-3.14159" upper="3.14159" velocity="0.0"/>
    </joint>
    <link name="Limb3">
        <inertial>
            <origin xyz="0 1.45 1.0" rpy="0 0 0"/>
            <mass value="1" />
            <inertia ixx="100" ixy="0" ixz="0" iyy="100" iyz="0" izz="100" />
        </inertial>
        <visual>
            <origin xyz="0 1.45 1.0" rpy="0 0 0"/>
            <geometry>
                <box size="2.3 2.9 1.5" />
            </geometry>
    <material name="green"/>
        </visual>
        <collision>
            <origin xyz="0 1.45 1.0" rpy="0 0 0"/>
            <geometry>
                <box size="2.3 2.9 1.5" />
            </geometry>
        </collision>
    </link>
    <joint name="Limb3_Limb6" type="revolute">
       <parent link="Limb3"/>
       <child  link="Limb6"/>
       <origin rpy="0 0 0" xyz="-1.15 0 0" />
     <axis xyz="0 1 0"/>
       <limit effort="0.0" lower="-3.14159" upper="3.14159" velocity="0.0"/>
    </joint>
    <link name="Limb6">
        <inertial>
            <origin xyz="-1.35 0 1.0" rpy="0 0 0"/>
            <mass value="1" />
            <inertia ixx="100" ixy="0" ixz="0" iyy="100" iyz="0" izz="100" />
        </inertial>
        <visual>
            <origin xyz="-1.35 0 1.0" rpy="0 0 0"/>
            <geometry>
                <box size="2.7 2.2 1.5" />
            </geometry>
    <material name="green"/>
        </visual>
        <collision>
            <origin xyz="-1.35 0 1.0" rpy="0 0 0"/>
            <geometry>
                <box size="2.7 2.2 1.5" />
            </geometry>
        </collision>
    </link>
    <joint name="Limb2_Limb7" type="revolute">
       <parent link="Limb2"/>
       <child  link="Limb7"/>
       <origin rpy="0 0 0" xyz="1.3 0 0" />
     <axis xyz="0 1 0"/>
       <limit effort="0.0" lower="-3.14159" upper="3.14159" velocity="0.0"/>
    </joint>
    <link name="Limb7">
        <inertial>
            <origin xyz="1.4 0 1.0" rpy="0 0 0"/>
            <mass value="1" />
            <inertia ixx="100" ixy="0" ixz="0" iyy="100" iyz="0" izz="100" />
        </inertial>
        <visual>
            <origin xyz="1.4 0 1.0" rpy="0 0 0"/>
            <geometry>
                <box size="2.8 2.2 1.5" />
            </geometry>
    <material name="green"/>
        </visual>
        <collision>
            <origin xyz="1.4 0 1.0" rpy="0 0 0"/>
            <geometry>
                <box size="2.8 2.2 1.5" />
            </geometry>
        </collision>
    </link>
    <joint name="Limb7_Limb8" type="revolute">
       <parent link="Limb7"/>
       <child  link="Limb8"/>
       <origin rpy="0 0 0" xyz="2.8 0 0" />
     <axis xyz="0 1 0"/>
       <limit effort="0.0" lower="-3.14159" upper="3.14159" velocity="0.0"/>
    </joint>
    <link name="Limb8">
        <inertial>
            <origin xyz="0.75 0 1.0" rpy="0 0 0"/>
            <mass value="1" />
            <inertia ixx="100" ixy="0" ixz="0" iyy="100" iyz="0" izz="100" />
        </inertial>
        <visual>
            <origin xyz="0.75 0 1.0" rpy="0 0 0"/>
            <geometry>
                <box size="1.5 2.2 1.5" />
            </geometry>
    <material name="green"/>
        </visual>
        <collision>
            <origin xyz="0.75 0 1.0" rpy="0 0 0"/>
            <geometry>
                <box size="1.5 2.2 1.5" />
            </geometry>
        </collision>
    </link>
    <joint name="Limb8_Limb9" type="revolute">
       <parent link="Limb8"/>
       <child  link="Limb9"/>
       <origin rpy="0 0 0" xyz="1.5 0 0" />
     <axis xyz="0 1 0"/>
       <limit effort="0.0" lower="-3.14159" upper="3.14159" velocity="0.0"/>
    </joint>
    <link name="Limb9">
        <inertial>
            <origin xyz="0.85 0 1.0" rpy="0 0 0"/>
            <mass value="1" />
            <inertia ixx="100" ixy="0" ixz="0" iyy="100" iyz="0" izz="100" />
        </inertial>
        <visual>
            <origin xyz="0.85 0 1.0" rpy="0 0 0"/>
            <geometry>
                <box size="1.7 2.2 1.5" />
            </geometry>
    <material name="green"/>
        </visual>
        <collision>
            <origin xyz="0.85 0 1.0" rpy="0 0 0"/>
            <geometry>
                <box size="1.7 2.2 1.5" />
            </geometry>
        </collision>
    </link>
    <joint name="Limb2_Limb10" type="revolute">
       <parent link="Limb2"/>
       <child  link="Limb10"/>
       <origin rpy="0 0 0" xyz="-1.3 0 0" />
     <axis xyz="0 1 0"/>
       <limit effort="0.0" lower="-3.14159" upper="3.14159" velocity="0.0"/>
    </joint>
    <link name="Limb10">
        <inertial>
            <origin xyz="-0.75 0 1.0" rpy="0 0 0"/>
            <mass value="1" />
            <inertia ixx="100" ixy="0" ixz="0" iyy="100" iyz="0" izz="100" />
        </inertial>
        <visual>
            <origin xyz="-0.75 0 1.0" rpy="0 0 0"/>
            <geometry>
                <box size="1.5 2.2 1.5" />
            </geometry>
    <material name="green"/>
        </visual>
        <collision>
            <origin xyz="-0.75 0 1.0" rpy="0 0 0"/>
            <geometry>
                <box size="1.5 2.2 1.5" />
            </geometry>
        </collision>
    </link>
    <joint name="Limb3_Limb11" type="revolute">
       <parent link="Limb3"/>
       <child  link="Limb11"/>
       <origin rpy="0 0 0" xyz="1.15 0 0" />
     <axis xyz="0 1 0"/>
       <limit effort="0.0" lower="-3.14159" upper="3.14159" velocity="0.0"/>
    </joint>
    <link name="Limb11">
        <inertial>
            <origin xyz="0.75 0 1.0" rpy="0 0 0"/>
            <mass value="1" />
            <inertia ixx="100" ixy="0" ixz="0" iyy="100" iyz="0" izz="100" />
        </inertial>
        <visual>
            <origin xyz="0.75 0 1.0" rpy="0 0 0"/>
            <geometry>
                <box size="1.5 2.2 1.5" />
            </geometry>
    <material name="green"/>
        </visual>
        <collision>
            <origin xyz="0.75 0 1.0" rpy="0 0 0"/>
            <geometry>
                <box size="1.5 2.2 1.5" />
            </geometry>
        </collision>
    </link>
    <joint name="Limb3_Limb12" type="revolute">
       <parent link="Limb3"/>
       <child  link="Limb12"/>
       <origin rpy="0 0 0" xyz="1.15 0 0" />
     <axis xyz="0 1 0"/>
       <limit effort="0.0" lower="-3.14159" upper="3.14159" velocity="0.0"/>
    </joint>
    <link name="Limb12">
        <inertial>
            <origin xyz="1.1 0 1.0" rpy="0 0 0"/>
            <mass value="1" />
            <inertia ixx="100" ixy="0" ixz="0" iyy="100" iyz="0" izz="100" />
        </inertial>
        <visual>
            <origin xyz="1.1 0 1.0" rpy="0 0 0"/>
            <geometry>
                <box size="2.2 2.2 1.5" />
            </geometry>
    <material name="green"/>
        </visual>
        <collision>
            <origin xyz="1.1 0 1.0" rpy="0 0 0"/>
            <geometry>
                <box size="2.2 2.2 1.5" />
            </geometry>
        </collision>
    </link>
</robot>