<robot name = "robot">
    <material name="blue">
        <color rgba="0 0.5 1.0 1.0"/>
    </material>
    <material name="green">
        <color rgba="0 1.0 0 1.0"/>
    </material>
    <link name="Limb0">
        <inertial>
            <origin xyz="0 0 1.0" rpy="0 0 0"/>
            <mass value="1" />
            <inertia ixx="100" ixy="0" ixz="0" iyy="100" iyz="0" izz="100" />
        </inertial>
        <visual>
            <origin xyz="0 0 1.0" rpy="0 0 0"/>
            <geometry>
                <box size="1.4 2.2 2.9" />
            </geometry>
    <material name="green"/>
        </visual>
        <collision>
            <origin xyz="0 0 1.0" rpy="0 0 0"/>
            <geometry>
                <box size="1.4 2.2 2.9" />
            </geometry>
        </collision>
    </link>
    <joint name="Limb0_Limb1" type="revolute">
       <parent link="Limb0"/>
       <child  link="Limb1"/>
       <origin rpy="0 0 0" xyz="0 1.1 0" />
     <axis xyz="1 0 0"/>
       <limit effort="0.0" lower="-3.14159" upper="3.14159" velocity="0.0"/>
    </joint>
    <link name="Limb1">
        <inertial>
            <origin xyz="0 0.95 1.0" rpy="0 0 0"/>
            <mass value="1" />
            <inertia ixx="100" ixy="0" ixz="0" iyy="100" iyz="0" izz="100" />
        </inertial>
        <visual>
            <origin xyz="0 0.95 1.0" rpy="0 0 0"/>
            <geometry>
                <box size="1.1 1.9 2.9" />
            </geometry>
    <material name="green"/>
        </visual>
        <collision>
            <origin xyz="0 0.95 1.0" rpy="0 0 0"/>
            <geometry>
                <box size="1.1 1.9 2.9" />
            </geometry>
        </collision>
    </link>
    <joint name="Limb1_Limb2" type="revolute">
       <parent link="Limb1"/>
       <child  link="Limb2"/>
       <origin rpy="0 0 0" xyz="0 1.9 0" />
     <axis xyz="1 0 0"/>
       <limit effort="0.0" lower="-3.14159" upper="3.14159" velocity="0.0"/>
    </joint>
    <link name="Limb2">
        <inertial>
            <origin xyz="0 0.85 1.0" rpy="0 0 0"/>
            <mass value="1" />
            <inertia ixx="100" ixy="0" ixz="0" iyy="100" iyz="0" izz="100" />
        </inertial>
        <visual>
            <origin xyz="0 0.85 1.0" rpy="0 0 0"/>
            <geometry>
                <box size="2.5 1.7 2.9" />
            </geometry>
    <material name="green"/>
        </visual>
        <collision>
            <origin xyz="0 0.85 1.0" rpy="0 0 0"/>
            <geometry>
                <box size="2.5 1.7 2.9" />
            </geometry>
        </collision>
    </link>
    <joint name="Limb2_Limb3" type="revolute">
       <parent link="Limb2"/>
       <child  link="Limb3"/>
       <origin rpy="0 0 0" xyz="0 1.7 0" />
     <axis xyz="1 0 0"/>
       <limit effort="0.0" lower="-3.14159" upper="3.14159" velocity="0.0"/>
    </joint>
    <link name="Limb3">
        <inertial>
            <origin xyz="0 0.5 1.0" rpy="0 0 0"/>
            <mass value="1" />
            <inertia ixx="100" ixy="0" ixz="0" iyy="100" iyz="0" izz="100" />
        </inertial>
        <visual>
            <origin xyz="0 0.5 1.0" rpy="0 0 0"/>
            <geometry>
                <box size="1.6 1.0 2.1" />
            </geometry>
    <material name="green"/>
        </visual>
        <collision>
            <origin xyz="0 0.5 1.0" rpy="0 0 0"/>
            <geometry>
                <box size="1.6 1.0 2.1" />
            </geometry>
        </collision>
    </link>
    <joint name="Limb2_Limb6" type="revolute">
       <parent link="Limb2"/>
       <child  link="Limb6"/>
       <origin rpy="0 0 0" xyz="1.25 0 0" />
     <axis xyz="0 1 0"/>
       <limit effort="0.0" lower="-3.14159" upper="3.14159" velocity="0.0"/>
    </joint>
    <link name="Limb6">
        <inertial>
            <origin xyz="1.15 0 1.0" rpy="0 0 0"/>
            <mass value="1" />
            <inertia ixx="100" ixy="0" ixz="0" iyy="100" iyz="0" izz="100" />
        </inertial>
        <visual>
            <origin xyz="1.15 0 1.0" rpy="0 0 0"/>
            <geometry>
                <box size="2.3 1.6 2.1" />
            </geometry>
    <material name="green"/>
        </visual>
        <collision>
            <origin xyz="1.15 0 1.0" rpy="0 0 0"/>
            <geometry>
                <box size="2.3 1.6 2.1" />
            </geometry>
        </collision>
    </link>
    <joint name="Limb3_Limb7" type="revolute">
       <parent link="Limb3"/>
       <child  link="Limb7"/>
       <origin rpy="0 0 0" xyz="-0.8 0 0" />
     <axis xyz="0 1 0"/>
       <limit effort="0.0" lower="-3.14159" upper="3.14159" velocity="0.0"/>
    </joint>
    <link name="Limb7">
        <inertial>
            <origin xyz="-1.1 0 1.0" rpy="0 0 0"/>
            <mass value="1" />
            <inertia ixx="100" ixy="0" ixz="0" iyy="100" iyz="0" izz="100" />
        </inertial>
        <visual>
            <origin xyz="-1.1 0 1.0" rpy="0 0 0"/>
            <geometry>
                <box size="2.2 1.6 2.1" />
            </geometry>
    <material name="green"/>
        </visual>
        <collision>
            <origin xyz="-1.1 0 1.0" rpy="0 0 0"/>
            <geometry>
                <box size="2.2 1.6 2.1" />
            </geometry>
        </collision>
    </link>
    <joint name="Limb2_Limb8" type="revolute">
       <parent link="Limb2"/>
       <child  link="Limb8"/>
       <origin rpy="0 0 0" xyz="1.25 0 0" />
     <axis xyz="0 1 0"/>
       <limit effort="0.0" lower="-3.14159" upper="3.14159" velocity="0.0"/>
    </joint>
    <link name="Limb8">
        <inertial>
            <origin xyz="1.0 0 1.0" rpy="0 0 0"/>
            <mass value="1" />
            <inertia ixx="100" ixy="0" ixz="0" iyy="100" iyz="0" izz="100" />
        </inertial>
        <visual>
            <origin xyz="1.0 0 1.0" rpy="0 0 0"/>
            <geometry>
                <box size="2.0 1.6 2.1" />
            </geometry>
    <material name="green"/>
        </visual>
        <collision>
            <origin xyz="1.0 0 1.0" rpy="0 0 0"/>
            <geometry>
                <box size="2.0 1.6 2.1" />
            </geometry>
        </collision>
    </link>
    <joint name="Limb3_Limb9" type="revolute">
       <parent link="Limb3"/>
       <child  link="Limb9"/>
       <origin rpy="0 0 0" xyz="-0.8 0 0" />
     <axis xyz="0 1 0"/>
       <limit effort="0.0" lower="-3.14159" upper="3.14159" velocity="0.0"/>
    </joint>
    <link name="Limb9">
        <inertial>
            <origin xyz="-0.5 0 1.0" rpy="0 0 0"/>
            <mass value="1" />
            <inertia ixx="100" ixy="0" ixz="0" iyy="100" iyz="0" izz="100" />
        </inertial>
        <visual>
            <origin xyz="-0.5 0 1.0" rpy="0 0 0"/>
            <geometry>
                <box size="1.0 1.6 2.1" />
            </geometry>
    <material name="green"/>
        </visual>
        <collision>
            <origin xyz="-0.5 0 1.0" rpy="0 0 0"/>
            <geometry>
                <box size="1.0 1.6 2.1" />
            </geometry>
        </collision>
    </link>
    <joint name="Limb2_Limb10" type="revolute">
       <parent link="Limb2"/>
       <child  link="Limb10"/>
       <origin rpy="0 0 0" xyz="-1.25 0 0" />
     <axis xyz="0 1 0"/>
       <limit effort="0.0" lower="-3.14159" upper="3.14159" velocity="0.0"/>
    </joint>
    <link name="Limb10">
        <inertial>
            <origin xyz="-0.9 0 1.0" rpy="0 0 0"/>
            <mass value="1" />
            <inertia ixx="100" ixy="0" ixz="0" iyy="100" iyz="0" izz="100" />
        </inertial>
        <visual>
            <origin xyz="-0.9 0 1.0" rpy="0 0 0"/>
            <geometry>
                <box size="1.8 1.6 2.1" />
            </geometry>
    <material name="green"/>
        </visual>
        <collision>
            <origin xyz="-0.9 0 1.0" rpy="0 0 0"/>
            <geometry>
                <box size="1.8 1.6 2.1" />
            </geometry>
        </collision>
    </link>
    <joint name="Limb2_Limb11" type="revolute">
       <parent link="Limb2"/>
       <child  link="Limb11"/>
       <origin rpy="0 0 0" xyz="1.25 0 0" />
     <axis xyz="0 1 0"/>
       <limit effort="0.0" lower="-3.14159" upper="3.14159" velocity="0.0"/>
    </joint>
    <link name="Limb11">
        <inertial>
            <origin xyz="1.05 0 1.0" rpy="0 0 0"/>
            <mass value="1" />
            <inertia ixx="100" ixy="0" ixz="0" iyy="100" iyz="0" izz="100" />
        </inertial>
        <visual>
            <origin xyz="1.05 0 1.0" rpy="0 0 0"/>
            <geometry>
                <box size="2.1 1.6 2.1" />
            </geometry>
    <material name="green"/>
        </visual>
        <collision>
            <origin xyz="1.05 0 1.0" rpy="0 0 0"/>
            <geometry>
                <box size="2.1 1.6 2.1" />
            </geometry>
        </collision>
    </link>
    <joint name="Limb3_Limb12" type="revolute">
       <parent link="Limb3"/>
       <child  link="Limb12"/>
       <origin rpy="0 0 0" xyz="-0.8 0 0" />
     <axis xyz="0 1 0"/>
       <limit effort="0.0" lower="-3.14159" upper="3.14159" velocity="0.0"/>
    </joint>
    <link name="Limb12">
        <inertial>
            <origin xyz="-0.95 0 1.0" rpy="0 0 0"/>
            <mass value="1" />
            <inertia ixx="100" ixy="0" ixz="0" iyy="100" iyz="0" izz="100" />
        </inertial>
        <visual>
            <origin xyz="-0.95 0 1.0" rpy="0 0 0"/>
            <geometry>
                <box size="1.9 1.6 2.1" />
            </geometry>
    <material name="green"/>
        </visual>
        <collision>
            <origin xyz="-0.95 0 1.0" rpy="0 0 0"/>
            <geometry>
                <box size="1.9 1.6 2.1" />
            </geometry>
        </collision>
    </link>
</robot>