<robot name = "robot">
    <material name="blue">
        <color rgba="0 0.5 1.0 1.0"/>
    </material>
    <material name="green">
        <color rgba="0 1.0 0 1.0"/>
    </material>
    <link name="Limb0">
        <inertial>
            <origin xyz="0 0 2.05" rpy="0 0 0"/>
            <mass value="1" />
            <inertia ixx="100" ixy="0" ixz="0" iyy="100" iyz="0" izz="100" />
        </inertial>
        <visual>
            <origin xyz="0 0 2.05" rpy="0 0 0"/>
            <geometry>
                <box size="1.0 1.9 2.1" />
            </geometry>
    <material name="blue"/>
        </visual>
        <collision>
            <origin xyz="0 0 2.05" rpy="0 0 0"/>
            <geometry>
                <box size="1.0 1.9 2.1" />
            </geometry>
        </collision>
    </link>
    <joint name="Limb0_BotLimb0" type="revolute">
       <parent link="Limb0"/>
       <child  link="BotLimb0"/>
       <origin rpy="0 0 0" xyz="0 0.95 3.1" />
     <axis xyz="1 0 0"/>
       <limit effort="0.0" lower="-3.14159" upper="3.14159" velocity="0.0"/>
    </joint>
    <link name="BotLimb0">
        <inertial>
            <origin xyz="0 0.95 1.05" rpy="0 0 0"/>
            <mass value="1" />
            <inertia ixx="100" ixy="0" ixz="0" iyy="100" iyz="0" izz="100" />
        </inertial>
        <visual>
            <origin xyz="0 0.95 1.05" rpy="0 0 0"/>
            <geometry>
                <box size="1.0 1.9 2.1" />
            </geometry>
    <material name="blue"/>
        </visual>
        <collision>
            <origin xyz="0 0.95 1.05" rpy="0 0 0"/>
            <geometry>
                <box size="1.0 1.9 2.1" />
            </geometry>
        </collision>
    </link>
    <joint name="BotLimb0_Limb1" type="revolute">
       <parent link="BotLimb0"/>
       <child  link="Limb1"/>
       <origin rpy="0 0 0" xyz="0 1.9 0" />
     <axis xyz="1 0 0"/>
       <limit effort="0.0" lower="-3.14159" upper="3.14159" velocity="0.0"/>
    </joint>
    <link name="Limb1">
        <inertial>
            <origin xyz="0 0.75 -0.85" rpy="0 0 0"/>
            <mass value="1" />
            <inertia ixx="100" ixy="0" ixz="0" iyy="100" iyz="0" izz="100" />
        </inertial>
        <visual>
            <origin xyz="0 0.75 -0.85" rpy="0 0 0"/>
            <geometry>
                <box size="1.9 1.5 1.7" />
            </geometry>
    <material name="blue"/>
        </visual>
        <collision>
            <origin xyz="0 0.75 -0.85" rpy="0 0 0"/>
            <geometry>
                <box size="1.9 1.5 1.7" />
            </geometry>
        </collision>
    </link>
    <joint name="Limb1_BotLimb1" type="revolute">
       <parent link="Limb1"/>
       <child  link="BotLimb1"/>
       <origin rpy="0 0 0" xyz="0 1.5 0" />
     <axis xyz="1 0 0"/>
       <limit effort="0.0" lower="-3.14159" upper="3.14159" velocity="0.0"/>
    </joint>
    <link name="BotLimb1">
        <inertial>
            <origin xyz="0 0.75 0.85" rpy="0 0 0"/>
            <mass value="1" />
            <inertia ixx="100" ixy="0" ixz="0" iyy="100" iyz="0" izz="100" />
        </inertial>
        <visual>
            <origin xyz="0 0.75 0.85" rpy="0 0 0"/>
            <geometry>
                <box size="1.9 1.5 1.7" />
            </geometry>
    <material name="blue"/>
        </visual>
        <collision>
            <origin xyz="0 0.75 0.85" rpy="0 0 0"/>
            <geometry>
                <box size="1.9 1.5 1.7" />
            </geometry>
        </collision>
    </link>
    <joint name="BotLimb1_Limb2" type="revolute">
       <parent link="BotLimb1"/>
       <child  link="Limb2"/>
       <origin rpy="0 0 0" xyz="0 1.5 0" />
     <axis xyz="1 0 0"/>
       <limit effort="0.0" lower="-3.14159" upper="3.14159" velocity="0.0"/>
    </joint>
    <link name="Limb2">
        <inertial>
            <origin xyz="0 0.8 -0.95" rpy="0 0 0"/>
            <mass value="1" />
            <inertia ixx="100" ixy="0" ixz="0" iyy="100" iyz="0" izz="100" />
        </inertial>
        <visual>
            <origin xyz="0 0.8 -0.95" rpy="0 0 0"/>
            <geometry>
                <box size="1.0 1.6 1.9" />
            </geometry>
    <material name="blue"/>
        </visual>
        <collision>
            <origin xyz="0 0.8 -0.95" rpy="0 0 0"/>
            <geometry>
                <box size="1.0 1.6 1.9" />
            </geometry>
        </collision>
    </link>
    <joint name="Limb2_BotLimb2" type="revolute">
       <parent link="Limb2"/>
       <child  link="BotLimb2"/>
       <origin rpy="0 0 0" xyz="0 1.6 0" />
     <axis xyz="1 0 0"/>
       <limit effort="0.0" lower="-3.14159" upper="3.14159" velocity="0.0"/>
    </joint>
    <link name="BotLimb2">
        <inertial>
            <origin xyz="0 0.8 0.95" rpy="0 0 0"/>
            <mass value="1" />
            <inertia ixx="100" ixy="0" ixz="0" iyy="100" iyz="0" izz="100" />
        </inertial>
        <visual>
            <origin xyz="0 0.8 0.95" rpy="0 0 0"/>
            <geometry>
                <box size="1.0 1.6 1.9" />
            </geometry>
    <material name="blue"/>
        </visual>
        <collision>
            <origin xyz="0 0.8 0.95" rpy="0 0 0"/>
            <geometry>
                <box size="1.0 1.6 1.9" />
            </geometry>
        </collision>
    </link>
    <joint name="BotLimb2_Limb3" type="revolute">
       <parent link="BotLimb2"/>
       <child  link="Limb3"/>
       <origin rpy="0 0 0" xyz="0 1.6 0" />
     <axis xyz="1 0 0"/>
       <limit effort="0.0" lower="-3.14159" upper="3.14159" velocity="0.0"/>
    </joint>
    <link name="Limb3">
        <inertial>
            <origin xyz="0 0.5 -0.8" rpy="0 0 0"/>
            <mass value="1" />
            <inertia ixx="100" ixy="0" ixz="0" iyy="100" iyz="0" izz="100" />
        </inertial>
        <visual>
            <origin xyz="0 0.5 -0.8" rpy="0 0 0"/>
            <geometry>
                <box size="0.9 1.0 1.6" />
            </geometry>
    <material name="green"/>
        </visual>
        <collision>
            <origin xyz="0 0.5 -0.8" rpy="0 0 0"/>
            <geometry>
                <box size="0.9 1.0 1.6" />
            </geometry>
        </collision>
    </link>
    <joint name="Limb3_BotLimb3" type="revolute">
       <parent link="Limb3"/>
       <child  link="BotLimb3"/>
       <origin rpy="0 0 0" xyz="0 1.0 0" />
     <axis xyz="1 0 0"/>
       <limit effort="0.0" lower="-3.14159" upper="3.14159" velocity="0.0"/>
    </joint>
    <link name="BotLimb3">
        <inertial>
            <origin xyz="0 0.5 0.8" rpy="0 0 0"/>
            <mass value="1" />
            <inertia ixx="100" ixy="0" ixz="0" iyy="100" iyz="0" izz="100" />
        </inertial>
        <visual>
            <origin xyz="0 0.5 0.8" rpy="0 0 0"/>
            <geometry>
                <box size="0.9 1.0 1.6" />
            </geometry>
    <material name="green"/>
        </visual>
        <collision>
            <origin xyz="0 0.5 0.8" rpy="0 0 0"/>
            <geometry>
                <box size="0.9 1.0 1.6" />
            </geometry>
        </collision>
    </link>
    <joint name="BotLimb3_Limb4" type="revolute">
       <parent link="BotLimb3"/>
       <child  link="Limb4"/>
       <origin rpy="0 0 0" xyz="0 1.0 0" />
     <axis xyz="1 0 0"/>
       <limit effort="0.0" lower="-3.14159" upper="3.14159" velocity="0.0"/>
    </joint>
    <link name="Limb4">
        <inertial>
            <origin xyz="0 0.55 -0.95" rpy="0 0 0"/>
            <mass value="1" />
            <inertia ixx="100" ixy="0" ixz="0" iyy="100" iyz="0" izz="100" />
        </inertial>
        <visual>
            <origin xyz="0 0.55 -0.95" rpy="0 0 0"/>
            <geometry>
                <box size="1.1 1.1 1.9" />
            </geometry>
    <material name="green"/>
        </visual>
        <collision>
            <origin xyz="0 0.55 -0.95" rpy="0 0 0"/>
            <geometry>
                <box size="1.1 1.1 1.9" />
            </geometry>
        </collision>
    </link>
    <joint name="Limb4_BotLimb4" type="revolute">
       <parent link="Limb4"/>
       <child  link="BotLimb4"/>
       <origin rpy="0 0 0" xyz="0 1.1 0" />
     <axis xyz="1 0 0"/>
       <limit effort="0.0" lower="-3.14159" upper="3.14159" velocity="0.0"/>
    </joint>
    <link name="BotLimb4">
        <inertial>
            <origin xyz="0 0.55 0.95" rpy="0 0 0"/>
            <mass value="1" />
            <inertia ixx="100" ixy="0" ixz="0" iyy="100" iyz="0" izz="100" />
        </inertial>
        <visual>
            <origin xyz="0 0.55 0.95" rpy="0 0 0"/>
            <geometry>
                <box size="1.1 1.1 1.9" />
            </geometry>
    <material name="green"/>
        </visual>
        <collision>
            <origin xyz="0 0.55 0.95" rpy="0 0 0"/>
            <geometry>
                <box size="1.1 1.1 1.9" />
            </geometry>
        </collision>
    </link>
    <joint name="BotLimb4_Limb5" type="revolute">
       <parent link="BotLimb4"/>
       <child  link="Limb5"/>
       <origin rpy="0 0 0" xyz="0 1.1 0" />
     <axis xyz="1 0 0"/>
       <limit effort="0.0" lower="-3.14159" upper="3.14159" velocity="0.0"/>
    </joint>
    <link name="Limb5">
        <inertial>
            <origin xyz="0 0.85 -1.0" rpy="0 0 0"/>
            <mass value="1" />
            <inertia ixx="100" ixy="0" ixz="0" iyy="100" iyz="0" izz="100" />
        </inertial>
        <visual>
            <origin xyz="0 0.85 -1.0" rpy="0 0 0"/>
            <geometry>
                <box size="1.2 1.7 2.0" />
            </geometry>
    <material name="blue"/>
        </visual>
        <collision>
            <origin xyz="0 0.85 -1.0" rpy="0 0 0"/>
            <geometry>
                <box size="1.2 1.7 2.0" />
            </geometry>
        </collision>
    </link>
    <joint name="Limb5_BotLimb5" type="revolute">
       <parent link="Limb5"/>
       <child  link="BotLimb5"/>
       <origin rpy="0 0 0" xyz="0 1.7 0" />
     <axis xyz="1 0 0"/>
       <limit effort="0.0" lower="-3.14159" upper="3.14159" velocity="0.0"/>
    </joint>
    <link name="BotLimb5">
        <inertial>
            <origin xyz="0 0.85 1.0" rpy="0 0 0"/>
            <mass value="1" />
            <inertia ixx="100" ixy="0" ixz="0" iyy="100" iyz="0" izz="100" />
        </inertial>
        <visual>
            <origin xyz="0 0.85 1.0" rpy="0 0 0"/>
            <geometry>
                <box size="1.2 1.7 2.0" />
            </geometry>
    <material name="blue"/>
        </visual>
        <collision>
            <origin xyz="0 0.85 1.0" rpy="0 0 0"/>
            <geometry>
                <box size="1.2 1.7 2.0" />
            </geometry>
        </collision>
    </link>
    <joint name="BotLimb5_Limb6" type="revolute">
       <parent link="BotLimb5"/>
       <child  link="Limb6"/>
       <origin rpy="0 0 0" xyz="0 1.7 0" />
     <axis xyz="1 0 0"/>
       <limit effort="0.0" lower="-3.14159" upper="3.14159" velocity="0.0"/>
    </joint>
    <link name="Limb6">
        <inertial>
            <origin xyz="0 0.95 1.05" rpy="0 0 0"/>
            <mass value="1" />
            <inertia ixx="100" ixy="0" ixz="0" iyy="100" iyz="0" izz="100" />
        </inertial>
        <visual>
            <origin xyz="0 0.95 1.05" rpy="0 0 0"/>
            <geometry>
                <box size="1.0 1.9 2.1" />
            </geometry>
    <material name="green"/>
        </visual>
        <collision>
            <origin xyz="0 0.95 1.05" rpy="0 0 0"/>
            <geometry>
                <box size="1.0 1.9 2.1" />
            </geometry>
        </collision>
    </link>
    <joint name="Limb3_Limb9" type="revolute">
       <parent link="Limb3"/>
       <child  link="Limb9"/>
       <origin rpy="0 0 0" xyz="0.45 0 -0.5" />
     <axis xyz="0 1 0"/>
       <limit effort="0.0" lower="-3.14159" upper="3.14159" velocity="0.0"/>
    </joint>
    <link name="Limb9">
        <inertial>
            <origin xyz="0.9 0 0" rpy="0 0 0"/>
            <mass value="1" />
            <inertia ixx="100" ixy="0" ixz="0" iyy="100" iyz="0" izz="100" />
        </inertial>
        <visual>
            <origin xyz="0.9 0 0" rpy="0 0 0"/>
            <geometry>
                <box size="1.8 2.2 2.7" />
            </geometry>
    <material name="green"/>
        </visual>
        <collision>
            <origin xyz="0.9 0 0" rpy="0 0 0"/>
            <geometry>
                <box size="1.8 2.2 2.7" />
            </geometry>
        </collision>
    </link>
    <joint name="Limb5_Limb10" type="revolute">
       <parent link="Limb5"/>
       <child  link="Limb10"/>
       <origin rpy="0 0 0" xyz="-0.6 0 -0.85" />
     <axis xyz="0 1 0"/>
       <limit effort="0.0" lower="-3.14159" upper="3.14159" velocity="0.0"/>
    </joint>
    <link name="Limb10">
        <inertial>
            <origin xyz="-1.05 0 0" rpy="0 0 0"/>
            <mass value="1" />
            <inertia ixx="100" ixy="0" ixz="0" iyy="100" iyz="0" izz="100" />
        </inertial>
        <visual>
            <origin xyz="-1.05 0 0" rpy="0 0 0"/>
            <geometry>
                <box size="2.1 2.2 2.7" />
            </geometry>
    <material name="green"/>
        </visual>
        <collision>
            <origin xyz="-1.05 0 0" rpy="0 0 0"/>
            <geometry>
                <box size="2.1 2.2 2.7" />
            </geometry>
        </collision>
    </link>
    <joint name="Limb4_Limb11" type="revolute">
       <parent link="Limb4"/>
       <child  link="Limb11"/>
       <origin rpy="0 0 0" xyz="-0.55 0 -0.55" />
     <axis xyz="0 1 0"/>
       <limit effort="0.0" lower="-3.14159" upper="3.14159" velocity="0.0"/>
    </joint>
    <link name="Limb11">
        <inertial>
            <origin xyz="-0.8 0 0" rpy="0 0 0"/>
            <mass value="1" />
            <inertia ixx="100" ixy="0" ixz="0" iyy="100" iyz="0" izz="100" />
        </inertial>
        <visual>
            <origin xyz="-0.8 0 0" rpy="0 0 0"/>
            <geometry>
                <box size="1.6 2.2 2.7" />
            </geometry>
    <material name="green"/>
        </visual>
        <collision>
            <origin xyz="-0.8 0 0" rpy="0 0 0"/>
            <geometry>
                <box size="1.6 2.2 2.7" />
            </geometry>
        </collision>
    </link>
    <joint name="Limb4_Limb12" type="revolute">
       <parent link="Limb4"/>
       <child  link="Limb12"/>
       <origin rpy="0 0 0" xyz="0.55 0 -0.55" />
     <axis xyz="0 1 0"/>
       <limit effort="0.0" lower="-3.14159" upper="3.14159" velocity="0.0"/>
    </joint>
    <link name="Limb12">
        <inertial>
            <origin xyz="0.55 0 0" rpy="0 0 0"/>
            <mass value="1" />
            <inertia ixx="100" ixy="0" ixz="0" iyy="100" iyz="0" izz="100" />
        </inertial>
        <visual>
            <origin xyz="0.55 0 0" rpy="0 0 0"/>
            <geometry>
                <box size="1.1 2.2 2.7" />
            </geometry>
    <material name="green"/>
        </visual>
        <collision>
            <origin xyz="0.55 0 0" rpy="0 0 0"/>
            <geometry>
                <box size="1.1 2.2 2.7" />
            </geometry>
        </collision>
    </link>
    <joint name="Limb6_Limb13" type="revolute">
       <parent link="Limb6"/>
       <child  link="Limb13"/>
       <origin rpy="0 0 0" xyz="-0.4 0 -0.5" />
     <axis xyz="0 1 0"/>
       <limit effort="0.0" lower="-3.14159" upper="3.14159" velocity="0.0"/>
    </joint>
    <link name="Limb13">
        <inertial>
            <origin xyz="-0.65 0 0" rpy="0 0 0"/>
            <mass value="1" />
            <inertia ixx="100" ixy="0" ixz="0" iyy="100" iyz="0" izz="100" />
        </inertial>
        <visual>
            <origin xyz="-0.65 0 0" rpy="0 0 0"/>
            <geometry>
                <box size="1.3 2.2 2.7" />
            </geometry>
    <material name="green"/>
        </visual>
        <collision>
            <origin xyz="-0.65 0 0" rpy="0 0 0"/>
            <geometry>
                <box size="1.3 2.2 2.7" />
            </geometry>
        </collision>
    </link>
    <joint name="Limb6_Limb15" type="revolute">
       <parent link="Limb6"/>
       <child  link="Limb15"/>
       <origin rpy="0 0 0" xyz="-0.4 0 -0.5" />
     <axis xyz="0 1 0"/>
       <limit effort="0.0" lower="-3.14159" upper="3.14159" velocity="0.0"/>
    </joint>
    <link name="Limb15">
        <inertial>
            <origin xyz="-0.4 0 0" rpy="0 0 0"/>
            <mass value="1" />
            <inertia ixx="100" ixy="0" ixz="0" iyy="100" iyz="0" izz="100" />
        </inertial>
        <visual>
            <origin xyz="-0.4 0 0" rpy="0 0 0"/>
            <geometry>
                <box size="0.8 2.2 2.7" />
            </geometry>
    <material name="green"/>
        </visual>
        <collision>
            <origin xyz="-0.4 0 0" rpy="0 0 0"/>
            <geometry>
                <box size="0.8 2.2 2.7" />
            </geometry>
        </collision>
    </link>
    <joint name="Limb5_Limb16" type="revolute">
       <parent link="Limb5"/>
       <child  link="Limb16"/>
       <origin rpy="0 0 0" xyz="-0.6 0 -0.85" />
     <axis xyz="0 1 0"/>
       <limit effort="0.0" lower="-3.14159" upper="3.14159" velocity="0.0"/>
    </joint>
    <link name="Limb16">
        <inertial>
            <origin xyz="-0.8 0 0" rpy="0 0 0"/>
            <mass value="1" />
            <inertia ixx="100" ixy="0" ixz="0" iyy="100" iyz="0" izz="100" />
        </inertial>
        <visual>
            <origin xyz="-0.8 0 0" rpy="0 0 0"/>
            <geometry>
                <box size="1.6 2.2 2.7" />
            </geometry>
    <material name="green"/>
        </visual>
        <collision>
            <origin xyz="-0.8 0 0" rpy="0 0 0"/>
            <geometry>
                <box size="1.6 2.2 2.7" />
            </geometry>
        </collision>
    </link>
    <joint name="Limb6_Limb18" type="revolute">
       <parent link="Limb6"/>
       <child  link="Limb18"/>
       <origin rpy="0 0 0" xyz="0.4 0 -0.5" />
     <axis xyz="0 1 0"/>
       <limit effort="0.0" lower="-3.14159" upper="3.14159" velocity="0.0"/>
    </joint>
    <link name="Limb18">
        <inertial>
            <origin xyz="0.45 0 0" rpy="0 0 0"/>
            <mass value="1" />
            <inertia ixx="100" ixy="0" ixz="0" iyy="100" iyz="0" izz="100" />
        </inertial>
        <visual>
            <origin xyz="0.45 0 0" rpy="0 0 0"/>
            <geometry>
                <box size="0.9 2.2 2.7" />
            </geometry>
    <material name="green"/>
        </visual>
        <collision>
            <origin xyz="0.45 0 0" rpy="0 0 0"/>
            <geometry>
                <box size="0.9 2.2 2.7" />
            </geometry>
        </collision>
    </link>
</robot>