<robot name = "robot">
    <link name="Limb0">
        <inertial>
            <origin xyz="0 0 1.0" rpy="0 0 0"/>
            <mass value="1" />
            <inertia ixx="100" ixy="0" ixz="0" iyy="100" iyz="0" izz="100" />
        </inertial>
        <visual>
            <origin xyz="0 0 1.0" rpy="0 0 0"/>
            <geometry>
                <box size="2.1 1.8 1.8" />
            </geometry>
            <material name="Cyan">
                <color rgba="0 1.0 1.0 1.0"/>
            </material>
        </visual>
        <collision>
            <origin xyz="0 0 1.0" rpy="0 0 0"/>
            <geometry>
                <box size="2.1 1.8 1.8" />
            </geometry>
        </collision>
    </link>
    <joint name="Limb0_Limb1" type="revolute">
       <parent link="Limb0"/>
       <child  link="Limb1"/>
       <origin rpy="0 0 0" xyz="0 0.525 0" />
     <axis xyz="1 0 0"/>
       <limit effort="0.0" lower="-3.14159" upper="3.14159" velocity="0.0"/>
    </joint>
    <link name="Limb1">
        <inertial>
            <origin xyz="0 1.3 1.0" rpy="0 0 0"/>
            <mass value="1" />
            <inertia ixx="100" ixy="0" ixz="0" iyy="100" iyz="0" izz="100" />
        </inertial>
        <visual>
            <origin xyz="0 1.3 1.0" rpy="0 0 0"/>
            <geometry>
                <box size="2.5 2.6 2.0" />
            </geometry>
            <material name="Cyan">
                <color rgba="0 1.0 1.0 1.0"/>
            </material>
        </visual>
        <collision>
            <origin xyz="0 1.3 1.0" rpy="0 0 0"/>
            <geometry>
                <box size="2.5 2.6 2.0" />
            </geometry>
        </collision>
    </link>
    <joint name="Limb1_Limb2" type="revolute">
       <parent link="Limb1"/>
       <child  link="Limb2"/>
       <origin rpy="0 0 0" xyz="0 2.6 0" />
     <axis xyz="1 0 0"/>
       <limit effort="0.0" lower="-3.14159" upper="3.14159" velocity="0.0"/>
    </joint>
    <link name="Limb2">
        <inertial>
            <origin xyz="0 0.95 1.0" rpy="0 0 0"/>
            <mass value="1" />
            <inertia ixx="100" ixy="0" ixz="0" iyy="100" iyz="0" izz="100" />
        </inertial>
        <visual>
            <origin xyz="0 0.95 1.0" rpy="0 0 0"/>
            <geometry>
                <box size="2.0 1.9 1.7" />
            </geometry>
            <material name="Cyan">
                <color rgba="0 1.0 1.0 1.0"/>
            </material>
        </visual>
        <collision>
            <origin xyz="0 0.95 1.0" rpy="0 0 0"/>
            <geometry>
                <box size="2.0 1.9 1.7" />
            </geometry>
        </collision>
    </link>
    <joint name="Limb2_Limb3" type="revolute">
       <parent link="Limb2"/>
       <child  link="Limb3"/>
       <origin rpy="0 0 0" xyz="0 1.9 0" />
     <axis xyz="1 0 0"/>
       <limit effort="0.0" lower="-3.14159" upper="3.14159" velocity="0.0"/>
    </joint>
    <link name="Limb3">
        <inertial>
            <origin xyz="0 1.0 1.0" rpy="0 0 0"/>
            <mass value="1" />
            <inertia ixx="100" ixy="0" ixz="0" iyy="100" iyz="0" izz="100" />
        </inertial>
        <visual>
            <origin xyz="0 1.0 1.0" rpy="0 0 0"/>
            <geometry>
                <box size="2.7 2.0 1.7" />
            </geometry>
            <material name="Cyan">
                <color rgba="0 1.0 1.0 1.0"/>
            </material>
        </visual>
        <collision>
            <origin xyz="0 1.0 1.0" rpy="0 0 0"/>
            <geometry>
                <box size="2.7 2.0 1.7" />
            </geometry>
        </collision>
    </link>
    <joint name="Limb3_Limb4" type="revolute">
       <parent link="Limb3"/>
       <child  link="Limb4"/>
       <origin rpy="0 0 0" xyz="0 2.0 0" />
     <axis xyz="1 0 0"/>
       <limit effort="0.0" lower="-3.14159" upper="3.14159" velocity="0.0"/>
    </joint>
    <link name="Limb4">
        <inertial>
            <origin xyz="0 1.45 1.0" rpy="0 0 0"/>
            <mass value="1" />
            <inertia ixx="100" ixy="0" ixz="0" iyy="100" iyz="0" izz="100" />
        </inertial>
        <visual>
            <origin xyz="0 1.45 1.0" rpy="0 0 0"/>
            <geometry>
                <box size="1.5 2.9 2.6" />
            </geometry>
            <material name="Cyan">
                <color rgba="0 1.0 1.0 1.0"/>
            </material>
        </visual>
        <collision>
            <origin xyz="0 1.45 1.0" rpy="0 0 0"/>
            <geometry>
                <box size="1.5 2.9 2.6" />
            </geometry>
        </collision>
    </link>
    <joint name="Limb4_Limb5" type="revolute">
       <parent link="Limb4"/>
       <child  link="Limb5"/>
       <origin rpy="0 0 0" xyz="0 2.9 0" />
     <axis xyz="1 0 0"/>
       <limit effort="0.0" lower="-3.14159" upper="3.14159" velocity="0.0"/>
    </joint>
    <link name="Limb5">
        <inertial>
            <origin xyz="0 0.75 1.0" rpy="0 0 0"/>
            <mass value="1" />
            <inertia ixx="100" ixy="0" ixz="0" iyy="100" iyz="0" izz="100" />
        </inertial>
        <visual>
            <origin xyz="0 0.75 1.0" rpy="0 0 0"/>
            <geometry>
                <box size="2.5 1.5 2.0" />
            </geometry>
            <material name="Cyan">
                <color rgba="0 1.0 1.0 1.0"/>
            </material>
        </visual>
        <collision>
            <origin xyz="0 0.75 1.0" rpy="0 0 0"/>
            <geometry>
                <box size="2.5 1.5 2.0" />
            </geometry>
        </collision>
    </link>
    <joint name="Limb5_Limb6" type="revolute">
       <parent link="Limb5"/>
       <child  link="Limb6"/>
       <origin rpy="0 0 0" xyz="0 1.5 0" />
     <axis xyz="1 0 0"/>
       <limit effort="0.0" lower="-3.14159" upper="3.14159" velocity="0.0"/>
    </joint>
    <link name="Limb6">
        <inertial>
            <origin xyz="0 1.4 1.0" rpy="0 0 0"/>
            <mass value="1" />
            <inertia ixx="100" ixy="0" ixz="0" iyy="100" iyz="0" izz="100" />
        </inertial>
        <visual>
            <origin xyz="0 1.4 1.0" rpy="0 0 0"/>
            <geometry>
                <box size="2.2 2.8 2.7" />
            </geometry>
            <material name="Cyan">
                <color rgba="0 1.0 1.0 1.0"/>
            </material>
        </visual>
        <collision>
            <origin xyz="0 1.4 1.0" rpy="0 0 0"/>
            <geometry>
                <box size="2.2 2.8 2.7" />
            </geometry>
        </collision>
    </link>
    <joint name="Limb6_Limb7" type="revolute">
       <parent link="Limb6"/>
       <child  link="Limb7"/>
       <origin rpy="0 0 0" xyz="0 2.8 0" />
     <axis xyz="1 0 0"/>
       <limit effort="0.0" lower="-3.14159" upper="3.14159" velocity="0.0"/>
    </joint>
    <link name="Limb7">
        <inertial>
            <origin xyz="0 1.2 1.0" rpy="0 0 0"/>
            <mass value="1" />
            <inertia ixx="100" ixy="0" ixz="0" iyy="100" iyz="0" izz="100" />
        </inertial>
        <visual>
            <origin xyz="0 1.2 1.0" rpy="0 0 0"/>
            <geometry>
                <box size="2.5 2.4 2.5" />
            </geometry>
            <material name="Cyan">
                <color rgba="0 1.0 1.0 1.0"/>
            </material>
        </visual>
        <collision>
            <origin xyz="0 1.2 1.0" rpy="0 0 0"/>
            <geometry>
                <box size="2.5 2.4 2.5" />
            </geometry>
        </collision>
    </link>
    <joint name="Limb7_Limb8" type="revolute">
       <parent link="Limb7"/>
       <child  link="Limb8"/>
       <origin rpy="0 0 0" xyz="0 2.4 0" />
     <axis xyz="1 0 0"/>
       <limit effort="0.0" lower="-3.14159" upper="3.14159" velocity="0.0"/>
    </joint>
    <link name="Limb8">
        <inertial>
            <origin xyz="0 0.9 1.0" rpy="0 0 0"/>
            <mass value="1" />
            <inertia ixx="100" ixy="0" ixz="0" iyy="100" iyz="0" izz="100" />
        </inertial>
        <visual>
            <origin xyz="0 0.9 1.0" rpy="0 0 0"/>
            <geometry>
                <box size="1.9 1.8 2.8" />
            </geometry>
            <material name="Cyan">
                <color rgba="0 1.0 1.0 1.0"/>
            </material>
        </visual>
        <collision>
            <origin xyz="0 0.9 1.0" rpy="0 0 0"/>
            <geometry>
                <box size="1.9 1.8 2.8" />
            </geometry>
        </collision>
    </link>
    <joint name="Limb8_Limb9" type="revolute">
       <parent link="Limb8"/>
       <child  link="Limb9"/>
       <origin rpy="0 0 0" xyz="0 1.8 0" />
     <axis xyz="1 0 0"/>
       <limit effort="0.0" lower="-3.14159" upper="3.14159" velocity="0.0"/>
    </joint>
    <link name="Limb9">
        <inertial>
            <origin xyz="0 0.8 1.0" rpy="0 0 0"/>
            <mass value="1" />
            <inertia ixx="100" ixy="0" ixz="0" iyy="100" iyz="0" izz="100" />
        </inertial>
        <visual>
            <origin xyz="0 0.8 1.0" rpy="0 0 0"/>
            <geometry>
                <box size="2.9 1.6 2.8" />
            </geometry>
            <material name="Cyan">
                <color rgba="0 1.0 1.0 1.0"/>
            </material>
        </visual>
        <collision>
            <origin xyz="0 0.8 1.0" rpy="0 0 0"/>
            <geometry>
                <box size="2.9 1.6 2.8" />
            </geometry>
        </collision>
    </link>
    <joint name="Limb9_Limb10" type="revolute">
       <parent link="Limb9"/>
       <child  link="Limb10"/>
       <origin rpy="0 0 0" xyz="0 1.6 0" />
     <axis xyz="1 0 0"/>
       <limit effort="0.0" lower="-3.14159" upper="3.14159" velocity="0.0"/>
    </joint>
    <link name="Limb10">
        <inertial>
            <origin xyz="0 1.3 1.0" rpy="0 0 0"/>
            <mass value="1" />
            <inertia ixx="100" ixy="0" ixz="0" iyy="100" iyz="0" izz="100" />
        </inertial>
        <visual>
            <origin xyz="0 1.3 1.0" rpy="0 0 0"/>
            <geometry>
                <box size="2.0 2.6 2.9" />
            </geometry>
            <material name="Cyan">
                <color rgba="0 1.0 1.0 1.0"/>
            </material>
        </visual>
        <collision>
            <origin xyz="0 1.3 1.0" rpy="0 0 0"/>
            <geometry>
                <box size="2.0 2.6 2.9" />
            </geometry>
        </collision>
    </link>
    <joint name="Limb10_Limb11" type="revolute">
       <parent link="Limb10"/>
       <child  link="Limb11"/>
       <origin rpy="0 0 0" xyz="0 2.6 0" />
     <axis xyz="1 0 0"/>
       <limit effort="0.0" lower="-3.14159" upper="3.14159" velocity="0.0"/>
    </joint>
    <link name="Limb11">
        <inertial>
            <origin xyz="0 1.1 1.0" rpy="0 0 0"/>
            <mass value="1" />
            <inertia ixx="100" ixy="0" ixz="0" iyy="100" iyz="0" izz="100" />
        </inertial>
        <visual>
            <origin xyz="0 1.1 1.0" rpy="0 0 0"/>
            <geometry>
                <box size="1.9 2.2 1.7" />
            </geometry>
            <material name="Cyan">
                <color rgba="0 1.0 1.0 1.0"/>
            </material>
        </visual>
        <collision>
            <origin xyz="0 1.1 1.0" rpy="0 0 0"/>
            <geometry>
                <box size="1.9 2.2 1.7" />
            </geometry>
        </collision>
    </link>
    <joint name="Limb11_Limb12" type="revolute">
       <parent link="Limb11"/>
       <child  link="Limb12"/>
       <origin rpy="0 0 0" xyz="0 2.2 0" />
     <axis xyz="1 0 0"/>
       <limit effort="0.0" lower="-3.14159" upper="3.14159" velocity="0.0"/>
    </joint>
    <link name="Limb12">
        <inertial>
            <origin xyz="0 0.75 1.0" rpy="0 0 0"/>
            <mass value="1" />
            <inertia ixx="100" ixy="0" ixz="0" iyy="100" iyz="0" izz="100" />
        </inertial>
        <visual>
            <origin xyz="0 0.75 1.0" rpy="0 0 0"/>
            <geometry>
                <box size="1.9 1.5 1.7" />
            </geometry>
            <material name="Cyan">
                <color rgba="0 1.0 1.0 1.0"/>
            </material>
        </visual>
        <collision>
            <origin xyz="0 0.75 1.0" rpy="0 0 0"/>
            <geometry>
                <box size="1.9 1.5 1.7" />
            </geometry>
        </collision>
    </link>
</robot>