<robot name = "robot">
    <material name="blue">
        <color rgba="0 0.5 1.0 1.0"/>
    </material>
    <material name="green">
        <color rgba="0 1.0 0 1.0"/>
    </material>
    <link name="Limb0">
        <inertial>
            <origin xyz="0 0 1.85" rpy="0 0 0"/>
            <mass value="1" />
            <inertia ixx="100" ixy="0" ixz="0" iyy="100" iyz="0" izz="100" />
        </inertial>
        <visual>
            <origin xyz="0 0 1.85" rpy="0 0 0"/>
            <geometry>
                <box size="1.7 1.3 1.7" />
            </geometry>
    <material name="blue"/>
        </visual>
        <collision>
            <origin xyz="0 0 1.85" rpy="0 0 0"/>
            <geometry>
                <box size="1.7 1.3 1.7" />
            </geometry>
        </collision>
    </link>
    <joint name="Limb0_BotLimb0" type="revolute">
       <parent link="Limb0"/>
       <child  link="BotLimb0"/>
       <origin rpy="0 0 0" xyz="0 0.65 2.7" />
     <axis xyz="1 0 0"/>
       <limit effort="0.0" lower="-3.14159" upper="3.14159" velocity="0.0"/>
    </joint>
    <link name="BotLimb0">
        <inertial>
            <origin xyz="0 0.65 0.85" rpy="0 0 0"/>
            <mass value="1" />
            <inertia ixx="100" ixy="0" ixz="0" iyy="100" iyz="0" izz="100" />
        </inertial>
        <visual>
            <origin xyz="0 0.65 0.85" rpy="0 0 0"/>
            <geometry>
                <box size="1.7 1.3 1.7" />
            </geometry>
    <material name="blue"/>
        </visual>
        <collision>
            <origin xyz="0 0.65 0.85" rpy="0 0 0"/>
            <geometry>
                <box size="1.7 1.3 1.7" />
            </geometry>
        </collision>
    </link>
    <joint name="BotLimb0_Limb1" type="revolute">
       <parent link="BotLimb0"/>
       <child  link="Limb1"/>
       <origin rpy="0 0 0" xyz="0 1.3 0" />
     <axis xyz="1 0 0"/>
       <limit effort="0.0" lower="-3.14159" upper="3.14159" velocity="0.0"/>
    </joint>
    <link name="Limb1">
        <inertial>
            <origin xyz="0 0.4 -0.7" rpy="0 0 0"/>
            <mass value="1" />
            <inertia ixx="100" ixy="0" ixz="0" iyy="100" iyz="0" izz="100" />
        </inertial>
        <visual>
            <origin xyz="0 0.4 -0.7" rpy="0 0 0"/>
            <geometry>
                <box size="1.1 0.8 1.4" />
            </geometry>
    <material name="green"/>
        </visual>
        <collision>
            <origin xyz="0 0.4 -0.7" rpy="0 0 0"/>
            <geometry>
                <box size="1.1 0.8 1.4" />
            </geometry>
        </collision>
    </link>
    <joint name="Limb1_BotLimb1" type="revolute">
       <parent link="Limb1"/>
       <child  link="BotLimb1"/>
       <origin rpy="0 0 0" xyz="0 0.8 0" />
     <axis xyz="1 0 0"/>
       <limit effort="0.0" lower="-3.14159" upper="3.14159" velocity="0.0"/>
    </joint>
    <link name="BotLimb1">
        <inertial>
            <origin xyz="0 0.4 0.7" rpy="0 0 0"/>
            <mass value="1" />
            <inertia ixx="100" ixy="0" ixz="0" iyy="100" iyz="0" izz="100" />
        </inertial>
        <visual>
            <origin xyz="0 0.4 0.7" rpy="0 0 0"/>
            <geometry>
                <box size="1.1 0.8 1.4" />
            </geometry>
    <material name="green"/>
        </visual>
        <collision>
            <origin xyz="0 0.4 0.7" rpy="0 0 0"/>
            <geometry>
                <box size="1.1 0.8 1.4" />
            </geometry>
        </collision>
    </link>
    <joint name="BotLimb1_Limb2" type="revolute">
       <parent link="BotLimb1"/>
       <child  link="Limb2"/>
       <origin rpy="0 0 0" xyz="0 0.8 0" />
     <axis xyz="1 0 0"/>
       <limit effort="0.0" lower="-3.14159" upper="3.14159" velocity="0.0"/>
    </joint>
    <link name="Limb2">
        <inertial>
            <origin xyz="0 0.85 -0.5" rpy="0 0 0"/>
            <mass value="1" />
            <inertia ixx="100" ixy="0" ixz="0" iyy="100" iyz="0" izz="100" />
        </inertial>
        <visual>
            <origin xyz="0 0.85 -0.5" rpy="0 0 0"/>
            <geometry>
                <box size="2.1 1.7 1.0" />
            </geometry>
    <material name="green"/>
        </visual>
        <collision>
            <origin xyz="0 0.85 -0.5" rpy="0 0 0"/>
            <geometry>
                <box size="2.1 1.7 1.0" />
            </geometry>
        </collision>
    </link>
    <joint name="Limb2_BotLimb2" type="revolute">
       <parent link="Limb2"/>
       <child  link="BotLimb2"/>
       <origin rpy="0 0 0" xyz="0 1.7 0" />
     <axis xyz="1 0 0"/>
       <limit effort="0.0" lower="-3.14159" upper="3.14159" velocity="0.0"/>
    </joint>
    <link name="BotLimb2">
        <inertial>
            <origin xyz="0 0.85 0.5" rpy="0 0 0"/>
            <mass value="1" />
            <inertia ixx="100" ixy="0" ixz="0" iyy="100" iyz="0" izz="100" />
        </inertial>
        <visual>
            <origin xyz="0 0.85 0.5" rpy="0 0 0"/>
            <geometry>
                <box size="2.1 1.7 1.0" />
            </geometry>
    <material name="green"/>
        </visual>
        <collision>
            <origin xyz="0 0.85 0.5" rpy="0 0 0"/>
            <geometry>
                <box size="2.1 1.7 1.0" />
            </geometry>
        </collision>
    </link>
    <joint name="BotLimb2_Limb3" type="revolute">
       <parent link="BotLimb2"/>
       <child  link="Limb3"/>
       <origin rpy="0 0 0" xyz="0 1.7 0" />
     <axis xyz="1 0 0"/>
       <limit effort="0.0" lower="-3.14159" upper="3.14159" velocity="0.0"/>
    </joint>
    <link name="Limb3">
        <inertial>
            <origin xyz="0 1.0 -0.9" rpy="0 0 0"/>
            <mass value="1" />
            <inertia ixx="100" ixy="0" ixz="0" iyy="100" iyz="0" izz="100" />
        </inertial>
        <visual>
            <origin xyz="0 1.0 -0.9" rpy="0 0 0"/>
            <geometry>
                <box size="0.8 2.0 1.8" />
            </geometry>
    <material name="blue"/>
        </visual>
        <collision>
            <origin xyz="0 1.0 -0.9" rpy="0 0 0"/>
            <geometry>
                <box size="0.8 2.0 1.8" />
            </geometry>
        </collision>
    </link>
    <joint name="Limb3_BotLimb3" type="revolute">
       <parent link="Limb3"/>
       <child  link="BotLimb3"/>
       <origin rpy="0 0 0" xyz="0 2.0 0" />
     <axis xyz="1 0 0"/>
       <limit effort="0.0" lower="-3.14159" upper="3.14159" velocity="0.0"/>
    </joint>
    <link name="BotLimb3">
        <inertial>
            <origin xyz="0 1.0 0.9" rpy="0 0 0"/>
            <mass value="1" />
            <inertia ixx="100" ixy="0" ixz="0" iyy="100" iyz="0" izz="100" />
        </inertial>
        <visual>
            <origin xyz="0 1.0 0.9" rpy="0 0 0"/>
            <geometry>
                <box size="0.8 2.0 1.8" />
            </geometry>
    <material name="blue"/>
        </visual>
        <collision>
            <origin xyz="0 1.0 0.9" rpy="0 0 0"/>
            <geometry>
                <box size="0.8 2.0 1.8" />
            </geometry>
        </collision>
    </link>
    <joint name="BotLimb3_Limb4" type="revolute">
       <parent link="BotLimb3"/>
       <child  link="Limb4"/>
       <origin rpy="0 0 0" xyz="0 2.0 0" />
     <axis xyz="1 0 0"/>
       <limit effort="0.0" lower="-3.14159" upper="3.14159" velocity="0.0"/>
    </joint>
    <link name="Limb4">
        <inertial>
            <origin xyz="0 0.85 -0.75" rpy="0 0 0"/>
            <mass value="1" />
            <inertia ixx="100" ixy="0" ixz="0" iyy="100" iyz="0" izz="100" />
        </inertial>
        <visual>
            <origin xyz="0 0.85 -0.75" rpy="0 0 0"/>
            <geometry>
                <box size="1.4 1.7 1.5" />
            </geometry>
    <material name="blue"/>
        </visual>
        <collision>
            <origin xyz="0 0.85 -0.75" rpy="0 0 0"/>
            <geometry>
                <box size="1.4 1.7 1.5" />
            </geometry>
        </collision>
    </link>
    <joint name="Limb4_BotLimb4" type="revolute">
       <parent link="Limb4"/>
       <child  link="BotLimb4"/>
       <origin rpy="0 0 0" xyz="0 1.7 0" />
     <axis xyz="1 0 0"/>
       <limit effort="0.0" lower="-3.14159" upper="3.14159" velocity="0.0"/>
    </joint>
    <link name="BotLimb4">
        <inertial>
            <origin xyz="0 0.85 0.75" rpy="0 0 0"/>
            <mass value="1" />
            <inertia ixx="100" ixy="0" ixz="0" iyy="100" iyz="0" izz="100" />
        </inertial>
        <visual>
            <origin xyz="0 0.85 0.75" rpy="0 0 0"/>
            <geometry>
                <box size="1.4 1.7 1.5" />
            </geometry>
    <material name="blue"/>
        </visual>
        <collision>
            <origin xyz="0 0.85 0.75" rpy="0 0 0"/>
            <geometry>
                <box size="1.4 1.7 1.5" />
            </geometry>
        </collision>
    </link>
    <joint name="BotLimb4_Limb5" type="revolute">
       <parent link="BotLimb4"/>
       <child  link="Limb5"/>
       <origin rpy="0 0 0" xyz="0 1.7 0" />
     <axis xyz="1 0 0"/>
       <limit effort="0.0" lower="-3.14159" upper="3.14159" velocity="0.0"/>
    </joint>
    <link name="Limb5">
        <inertial>
            <origin xyz="0 0.65 0.85" rpy="0 0 0"/>
            <mass value="1" />
            <inertia ixx="100" ixy="0" ixz="0" iyy="100" iyz="0" izz="100" />
        </inertial>
        <visual>
            <origin xyz="0 0.65 0.85" rpy="0 0 0"/>
            <geometry>
                <box size="1.7 1.3 1.7" />
            </geometry>
    <material name="blue"/>
        </visual>
        <collision>
            <origin xyz="0 0.65 0.85" rpy="0 0 0"/>
            <geometry>
                <box size="1.7 1.3 1.7" />
            </geometry>
        </collision>
    </link>
    <joint name="Limb2_Limb8" type="revolute">
       <parent link="Limb2"/>
       <child  link="Limb8"/>
       <origin rpy="0 0 0" xyz="-1.05 0 -0.85" />
     <axis xyz="0 1 0"/>
       <limit effort="0.0" lower="-3.14159" upper="3.14159" velocity="0.0"/>
    </joint>
    <link name="Limb8">
        <inertial>
            <origin xyz="-0.9 0 0" rpy="0 0 0"/>
            <mass value="1" />
            <inertia ixx="100" ixy="0" ixz="0" iyy="100" iyz="0" izz="100" />
        </inertial>
        <visual>
            <origin xyz="-0.9 0 0" rpy="0 0 0"/>
            <geometry>
                <box size="1.8 2.3 1.5" />
            </geometry>
    <material name="blue"/>
        </visual>
        <collision>
            <origin xyz="-0.9 0 0" rpy="0 0 0"/>
            <geometry>
                <box size="1.8 2.3 1.5" />
            </geometry>
        </collision>
    </link>
    <joint name="Limb3_Limb9" type="revolute">
       <parent link="Limb3"/>
       <child  link="Limb9"/>
       <origin rpy="0 0 0" xyz="0.4 0 -1.0" />
     <axis xyz="0 1 0"/>
       <limit effort="0.0" lower="-3.14159" upper="3.14159" velocity="0.0"/>
    </joint>
    <link name="Limb9">
        <inertial>
            <origin xyz="0.45 0 0" rpy="0 0 0"/>
            <mass value="1" />
            <inertia ixx="100" ixy="0" ixz="0" iyy="100" iyz="0" izz="100" />
        </inertial>
        <visual>
            <origin xyz="0.45 0 0" rpy="0 0 0"/>
            <geometry>
                <box size="0.9 2.3 1.5" />
            </geometry>
    <material name="blue"/>
        </visual>
        <collision>
            <origin xyz="0.45 0 0" rpy="0 0 0"/>
            <geometry>
                <box size="0.9 2.3 1.5" />
            </geometry>
        </collision>
    </link>
    <joint name="Limb2_Limb10" type="revolute">
       <parent link="Limb2"/>
       <child  link="Limb10"/>
       <origin rpy="0 0 0" xyz="-1.05 0 -0.85" />
     <axis xyz="0 1 0"/>
       <limit effort="0.0" lower="-3.14159" upper="3.14159" velocity="0.0"/>
    </joint>
    <link name="Limb10">
        <inertial>
            <origin xyz="-0.7 0 0" rpy="0 0 0"/>
            <mass value="1" />
            <inertia ixx="100" ixy="0" ixz="0" iyy="100" iyz="0" izz="100" />
        </inertial>
        <visual>
            <origin xyz="-0.7 0 0" rpy="0 0 0"/>
            <geometry>
                <box size="1.4 2.3 1.5" />
            </geometry>
    <material name="blue"/>
        </visual>
        <collision>
            <origin xyz="-0.7 0 0" rpy="0 0 0"/>
            <geometry>
                <box size="1.4 2.3 1.5" />
            </geometry>
        </collision>
    </link>
    <joint name="Limb5_Limb11" type="revolute">
       <parent link="Limb5"/>
       <child  link="Limb11"/>
       <origin rpy="0 0 0" xyz="-0.9 0 -0.75" />
     <axis xyz="0 1 0"/>
       <limit effort="0.0" lower="-3.14159" upper="3.14159" velocity="0.0"/>
    </joint>
    <link name="Limb11">
        <inertial>
            <origin xyz="-1.0 0 0" rpy="0 0 0"/>
            <mass value="1" />
            <inertia ixx="100" ixy="0" ixz="0" iyy="100" iyz="0" izz="100" />
        </inertial>
        <visual>
            <origin xyz="-1.0 0 0" rpy="0 0 0"/>
            <geometry>
                <box size="2.0 2.3 1.5" />
            </geometry>
    <material name="blue"/>
        </visual>
        <collision>
            <origin xyz="-1.0 0 0" rpy="0 0 0"/>
            <geometry>
                <box size="2.0 2.3 1.5" />
            </geometry>
        </collision>
    </link>
    <joint name="Limb2_Limb14" type="revolute">
       <parent link="Limb2"/>
       <child  link="Limb14"/>
       <origin rpy="0 0 0" xyz="1.05 0 -0.85" />
     <axis xyz="0 1 0"/>
       <limit effort="0.0" lower="-3.14159" upper="3.14159" velocity="0.0"/>
    </joint>
    <link name="Limb14">
        <inertial>
            <origin xyz="0.4 0 0" rpy="0 0 0"/>
            <mass value="1" />
            <inertia ixx="100" ixy="0" ixz="0" iyy="100" iyz="0" izz="100" />
        </inertial>
        <visual>
            <origin xyz="0.4 0 0" rpy="0 0 0"/>
            <geometry>
                <box size="0.8 2.3 1.5" />
            </geometry>
    <material name="blue"/>
        </visual>
        <collision>
            <origin xyz="0.4 0 0" rpy="0 0 0"/>
            <geometry>
                <box size="0.8 2.3 1.5" />
            </geometry>
        </collision>
    </link>
    <joint name="Limb4_Limb17" type="revolute">
       <parent link="Limb4"/>
       <child  link="Limb17"/>
       <origin rpy="0 0 0" xyz="0.7 0 -0.85" />
     <axis xyz="0 1 0"/>
       <limit effort="0.0" lower="-3.14159" upper="3.14159" velocity="0.0"/>
    </joint>
    <link name="Limb17">
        <inertial>
            <origin xyz="0.95 0 0" rpy="0 0 0"/>
            <mass value="1" />
            <inertia ixx="100" ixy="0" ixz="0" iyy="100" iyz="0" izz="100" />
        </inertial>
        <visual>
            <origin xyz="0.95 0 0" rpy="0 0 0"/>
            <geometry>
                <box size="1.9 2.3 1.5" />
            </geometry>
    <material name="blue"/>
        </visual>
        <collision>
            <origin xyz="0.95 0 0" rpy="0 0 0"/>
            <geometry>
                <box size="1.9 2.3 1.5" />
            </geometry>
        </collision>
    </link>
</robot>