<robot name = "robot">
    <material name="blue">
        <color rgba="0 0.5 1.0 1.0"/>
    </material>
    <material name="green">
        <color rgba="0 1.0 0 1.0"/>
    </material>
    <link name="Limb0">
        <inertial>
            <origin xyz="0 0 0.55" rpy="0 0 0"/>
            <mass value="1" />
            <inertia ixx="100" ixy="0" ixz="0" iyy="100" iyz="0" izz="100" />
        </inertial>
        <visual>
            <origin xyz="0 0 0.55" rpy="0 0 0"/>
            <geometry>
                <box size="1.4 0.7 1.1" />
            </geometry>
    <material name="green"/>
        </visual>
        <collision>
            <origin xyz="0 0 0.55" rpy="0 0 0"/>
            <geometry>
                <box size="1.4 0.7 1.1" />
            </geometry>
        </collision>
    </link>
    <joint name="Limb0_BotLimb0" type="revolute">
       <parent link="Limb0"/>
       <child  link="BotLimb0"/>
       <origin rpy="0 0 0" xyz="0 0.35 1.1" />
     <axis xyz="1 0 0"/>
       <limit effort="0.0" lower="-3.14159" upper="3.14159" velocity="0.0"/>
    </joint>
    <link name="BotLimb0">
        <inertial>
            <origin xyz="0 0.35 0.55" rpy="0 0 0"/>
            <mass value="1" />
            <inertia ixx="100" ixy="0" ixz="0" iyy="100" iyz="0" izz="100" />
        </inertial>
        <visual>
            <origin xyz="0 0.35 0.55" rpy="0 0 0"/>
            <geometry>
                <box size="1.4 0.7 1.1" />
            </geometry>
    <material name="green"/>
        </visual>
        <collision>
            <origin xyz="0 0.35 0.55" rpy="0 0 0"/>
            <geometry>
                <box size="1.4 0.7 1.1" />
            </geometry>
        </collision>
    </link>
    <joint name="BotLimb0_Limb1" type="revolute">
       <parent link="BotLimb0"/>
       <child  link="Limb1"/>
       <origin rpy="0 0 0" xyz="0 0.7 0" />
     <axis xyz="1 0 0"/>
       <limit effort="0.0" lower="-3.14159" upper="3.14159" velocity="0.0"/>
    </joint>
    <link name="Limb1">
        <inertial>
            <origin xyz="0 0.35 -0.7" rpy="0 0 0"/>
            <mass value="1" />
            <inertia ixx="100" ixy="0" ixz="0" iyy="100" iyz="0" izz="100" />
        </inertial>
        <visual>
            <origin xyz="0 0.35 -0.7" rpy="0 0 0"/>
            <geometry>
                <box size="0.7 0.7 1.4" />
            </geometry>
    <material name="green"/>
        </visual>
        <collision>
            <origin xyz="0 0.35 -0.7" rpy="0 0 0"/>
            <geometry>
                <box size="0.7 0.7 1.4" />
            </geometry>
        </collision>
    </link>
    <joint name="Limb1_BotLimb1" type="revolute">
       <parent link="Limb1"/>
       <child  link="BotLimb1"/>
       <origin rpy="0 0 0" xyz="0 0.7 0" />
     <axis xyz="1 0 0"/>
       <limit effort="0.0" lower="-3.14159" upper="3.14159" velocity="0.0"/>
    </joint>
    <link name="BotLimb1">
        <inertial>
            <origin xyz="0 0.35 0.7" rpy="0 0 0"/>
            <mass value="1" />
            <inertia ixx="100" ixy="0" ixz="0" iyy="100" iyz="0" izz="100" />
        </inertial>
        <visual>
            <origin xyz="0 0.35 0.7" rpy="0 0 0"/>
            <geometry>
                <box size="0.7 0.7 1.4" />
            </geometry>
    <material name="green"/>
        </visual>
        <collision>
            <origin xyz="0 0.35 0.7" rpy="0 0 0"/>
            <geometry>
                <box size="0.7 0.7 1.4" />
            </geometry>
        </collision>
    </link>
    <joint name="BotLimb1_Limb2" type="revolute">
       <parent link="BotLimb1"/>
       <child  link="Limb2"/>
       <origin rpy="0 0 0" xyz="0 0.7 0" />
     <axis xyz="1 0 0"/>
       <limit effort="0.0" lower="-3.14159" upper="3.14159" velocity="0.0"/>
    </joint>
    <link name="Limb2">
        <inertial>
            <origin xyz="0 0.4 0.55" rpy="0 0 0"/>
            <mass value="1" />
            <inertia ixx="100" ixy="0" ixz="0" iyy="100" iyz="0" izz="100" />
        </inertial>
        <visual>
            <origin xyz="0 0.4 0.55" rpy="0 0 0"/>
            <geometry>
                <box size="1.4 0.7 1.1" />
            </geometry>
    <material name="green"/>
        </visual>
        <collision>
            <origin xyz="0 0.4 0.55" rpy="0 0 0"/>
            <geometry>
                <box size="1.4 0.7 1.1" />
            </geometry>
        </collision>
    </link>
</robot>